Workbook
Name ___a65537: [1]BLSHEET06!#REF!
Name ___a65537: [1]BLSHEET06!#REF!
Name ___a65537: [1]BLSHEET06!#REF!
Name ___a65537: [1]BLSHEET06!#REF!
Name ___a65537: [1]BLSHEET06!#REF!
Name ___a65537: [1]BLSHEET06!#REF!
Name ___a65537: [1]BLSHEET06!#REF!
Name ___a65537: [1]BLSHEET06!#REF!
Name ___a65537: [1]BLSHEET06!#REF!
Name ___a65537: [1]BLSHEET06!#REF!
Name __a65537: [1]BLSHEET06!#REF!
Name __a65537: [1]BLSHEET06!#REF!
Name __a65537: [1]BLSHEET06!#REF!
Name __a65537: [1]BLSHEET06!#REF!
Name __a65537: [1]BLSHEET06!#REF!
Name __a65537: [1]BLSHEET06!#REF!
Name __a65537: [1]BLSHEET06!#REF!
Name __a65537: [1]BLSHEET06!#REF!
Name __a65537: [1]BLSHEET06!#REF!
Name __a65537: [1]BLSHEET06!#REF!
Name __jj102: #REF!
Name _a65537: [1]BLSHEET06!#REF!
Name _a65537: [1]BLSHEET06!#REF!
Name _a65537: [1]BLSHEET06!#REF!
Name _a65537: [1]BLSHEET06!#REF!
Name _a65537: [1]BLSHEET06!#REF!
Name _a65537: [1]BLSHEET06!#REF!
Name _a65537: [1]BLSHEET06!#REF!
Name _a65537: [1]BLSHEET06!#REF!
Name _a65537: [1]BLSHEET06!#REF!
Name _a65537: [1]BLSHEET06!#REF!
Name _a65537: [1]BLSHEET06!#REF!
Name _jj102: #REF!
Name A: [2]BLSHEET06!#REF!
Name A: [2]BLSHEET06!#REF!
Name A: [2]BLSHEET06!#REF!
Name A: [2]BLSHEET06!#REF!
Name A: [2]BLSHEET06!#REF!
Name A: [2]BLSHEET06!#REF!
Name A: [2]BLSHEET06!#REF!
Name A: [2]BLSHEET06!#REF!
Name A: [2]BLSHEET06!#REF!
Name A: [2]BLSHEET06!#REF!
Name A: [2]BLSHEET06!#REF!
Name a17J554: [3]Sheet4!#REF!
Name a17J554: [3]Sheet4!#REF!
Name a17J554: [3]Sheet4!#REF!
Name a17J554: [3]Sheet4!#REF!
Name a17J554: [3]Sheet4!#REF!
Name a17J554: [3]Sheet4!#REF!
Name a17J554: [3]Sheet4!#REF!
Name a17J554: [3]Sheet4!#REF!
Name a17J554: [3]Sheet4!#REF!
Name a17J554: [3]Sheet4!#REF!
Name abc: [1]BLSHEET06!#REF!
Name abc: [1]BLSHEET06!#REF!
Name abc: [1]BLSHEET06!#REF!
Name abc: [1]BLSHEET06!#REF!
Name abc: [1]BLSHEET06!#REF!
Name abc: [1]BLSHEET06!#REF!

Sheet Req_PNB
C1: FINANCIAL ANALYSIS :
I2: (Rs. In Lacs)
D3: 2014-15 | E3: 2015-16 | F3: 2016-17 | G3: 2017-18 | H3: 2018-19 | I3: 2019-20 | J3: 2020-21 | K3: 2021-22 | L3: 2022-23
D4: (Projected)
C5: Gross turnover
C6: - Domestic | D6: ='P L '!D29-D10 -> 1961.7343 | E6: ='P L '!E29-E10 -> 1961.7343 | F6: ='P L '!F29-F10 -> 2206.9511 | G6: ='P L '!G29-G10 -> 2452.1678 | H6: ='P L '!H29-H10 -> 2697.3846 | I6: ='P L '!I29-I10 -> 2942.6014 | J6: ='P L '!J29-J10 -> 3187.8182 | K6: ='P L '!K29-K10 -> 3433.035 | L6: ='P L '!L29-L10 -> 2942.6014
C7: - Export
C8: % growth * | E8: =(E6-D6)/D6*100 -> 0 | F8: =(F6-E6)/E6*100 -> 12.5 | G8: =(G6-F6)/F6*100 -> 11.111111 | H8: =(H6-G6)/G6*100 -> 10 | I8: =(I6-H6)/H6*100 -> 9.0909091 | J8: =(J6-I6)/I6*100 -> 8.3333333 | K8: =(K6-J6)/J6*100 -> 7.6923077 | L8: =(L6-K6)/K6*100 -> -14.285714
C9: Net sales (net of excise duty etc.) | D9: =D6 -> 1961.7343 | E9: =E6 -> 1961.7343 | F9: =F6 -> 2206.9511 | G9: =G6 -> 2452.1678 | H9: =H6 -> 2697.3846 | I9: =I6 -> 2942.6014 | J9: =J6 -> 3187.8182 | K9: =K6 -> 3433.035 | L9: =L6 -> 2942.6014
C10: Other income | D10: ='P L '!D28 -> 50.300879 | E10: ='P L '!E28 -> 50.300879 | F10: ='P L '!F28 -> 56.588489 | G10: ='P L '!G28 -> 62.876099 | H10: ='P L '!H28 -> 69.163708 | I10: ='P L '!I28 -> 75.451318 | J10: ='P L '!J28 -> 81.738928 | K10: ='P L '!K28 -> 88.026538 | L10: ='P L '!L28 -> 75.451318
C11: Operating profit/ loss* | D11: =#REF! -> #REF! | E11: =#REF! -> #REF! | F11: =#REF! -> #REF! | G11: =#REF! -> #REF! | H11: =#REF! -> #REF! | I11: =#REF! -> #REF! | J11: =#REF! -> #REF! | K11: =#REF! -> #REF! | L11: =#REF! -> #REF!
C12: Profit before tax | D12: =#REF! -> #REF! | E12: =#REF! -> #REF! | F12: =#REF! -> #REF! | G12: =#REF! -> #REF! | H12: =#REF! -> #REF! | I12: =#REF! -> #REF! | J12: =#REF! -> #REF! | K12: =#REF! -> #REF! | L12: =#REF! -> #REF!
C13: Profit after tax | D13: =#REF! -> #REF! | E13: =#REF! -> #REF! | F13: =#REF! -> #REF! | G13: =#REF! -> #REF! | H13: =#REF! -> #REF! | I13: =#REF! -> #REF! | J13: =#REF! -> #REF! | K13: =#REF! -> #REF! | L13: =#REF! -> #REF!
C14: Depreciation | D14: =#REF! -> #REF! | E14: =#REF! -> #REF! | F14: =#REF! -> #REF! | G14: =#REF! -> #REF! | H14: =#REF! -> #REF! | I14: =#REF! -> #REF! | J14: =#REF! -> #REF! | K14: =#REF! -> #REF! | L14: =#REF! -> #REF!
C15: Cash profit/ (loss) * | D15: =D13+D14 -> #REF! | E15: =E13+E14 -> #REF! | F15: =F13+F14 -> #REF! | G15: =G13+G14 -> #REF! | H15: =H13+H14 -> #REF! | I15: =I13+I14 -> #REF! | J15: =J13+J14 -> #REF! | K15: =K13+K14 -> #REF! | L15: =L13+L14 -> #REF!
C16: EBIDTA/PBIDTA | D16: =#REF!+#REF!+#REF!+#REF!+#REF! -> #REF! | E16: =#REF!+#REF!+#REF!+#REF!+#REF! -> #REF! | F16: =#REF!+#REF!+#REF!+#REF!+#REF! -> #REF! | G16: =#REF!+#REF!+#REF!+#REF!+#REF! -> #REF! | H16: =#REF!+#REF!+#REF!+#REF!+#REF! -> #REF! | I16: =#REF!+#REF!+#REF!+#REF!+#REF! -> #REF! | J16: =#REF!+#REF!+#REF!+#REF!+#REF! -> #REF! | K16: =#REF!+#REF!+#REF!+#REF!+#REF! -> #REF! | L16: =#REF!+#REF!+#REF!+#REF!+#REF! -> #REF!
C17: Paid up capital | D17: =#REF! -> #REF! | E17: =#REF! -> #REF! | F17: =#REF! -> #REF! | G17: =#REF! -> #REF! | H17: =#REF! -> #REF! | I17: =#REF! -> #REF! | J17: =#REF! -> #REF! | K17: =#REF! -> #REF! | L17: =#REF! -> #REF!
C18: Unsecured loan (quasi capital) | D18: =#REF! -> #REF! | E18: =#REF! -> #REF! | F18: =#REF! -> #REF! | G18: =#REF! -> #REF! | H18: =#REF! -> #REF! | I18: =#REF! -> #REF! | J18: =#REF! -> #REF! | K18: =#REF! -> #REF! | L18: =#REF! -> #REF!
C19: Reserves and surplus excluding revaluation reserves | D19: =#REF! -> #REF! | E19: =#REF! -> #REF! | F19: =#REF! -> #REF! | G19: =#REF! -> #REF! | H19: =#REF! -> #REF! | I19: =#REF! -> #REF! | J19: =#REF! -> #REF! | K19: =#REF! -> #REF! | L19: =#REF! -> #REF!
C20: Misc. expenditure not written off | D20: 0 | E20: 0 | F20: 0 | G20: 0 | H20: 0 | I20: 0 | J20: 0 | K20: 0 | L20: 0
C21: Accumulated losses * | D21: 0 | E21: 0 | F21: 0 | G21: 0 | H21: 0 | I21: 0 | J21: 0 | K21: 0 | L21: 0
C22: Deferred tax liability/ asset | D22: 0 | E22: 0 | F22: 0 | G22: 0 | H22: 0 | I22: 0 | J22: 0 | K22: 0 | L22: 0
C23: a) Tangible Net Worth | D23: =#REF! -> #REF! | E23: =#REF! -> #REF! | F23: =#REF! -> #REF! | G23: =#REF! -> #REF! | H23: =#REF! -> #REF! | I23: =#REF! -> #REF! | J23: =#REF! -> #REF! | K23: =#REF! -> #REF! | L23: =#REF! -> #REF! | N23: =D23-D17-D19 -> #REF! | O23: =E23-E17-E19 -> #REF! | P23: =F23-F17-F19 -> #REF! | Q23: =G23-G17-G19 -> #REF! | R23: =H23-H17-H19 -> #REF! | S23: =I23-I17-I19 -> #REF! | T23: =J23-J17-J19 -> #REF! | U23: =K23-K17-K19 -> #REF! | V23: =L23-L17-L19 -> #REF!
C24: b) Investment in allied concerns and amount of cross holdings | D24: 0 | E24: 0 | F24: 0 | G24: 0 | H24: 0 | I24: 0 | J24: 0 | K24: 0 | L24: 0
C25: c) Net owned funds/Adjusted TNW 9a-b)* | D25: =D23-D24 -> #REF! | E25: =E23-E24 -> #REF! | F25: =F23-F24 -> #REF! | G25: =G23-G24 -> #REF! | H25: =H23-H24 -> #REF! | I25: =I23-I24 -> #REF! | J25: =J23-J24 -> #REF! | K25: =K23-K24 -> #REF! | L25: =L23-L24 -> #REF!
C26: Share application money | D26: 0 | E26: 0 | F26: 0 | G26: 0 | H26: 0 | I26: 0 | J26: 0 | K26: 0 | L26: 0
C27: Total Borrowings | D27: ='B S '!E28+'B S '!E29+'B S '!E30 -> 2830 | E27: ='B S '!F28+'B S '!F29+'B S '!F30 -> 2530 | F27: ='B S '!G28+'B S '!G29+'B S '!G30 -> 2170 | G27: ='B S '!H28+'B S '!H29+'B S '!H30 -> 1690 | H27: ='B S '!I28+'B S '!I29+'B S '!I30 -> 1070 | I27: ='B S '!J28+'B S '!J29+'B S '!J30 -> 406 | J27: ='B S '!K28+'B S '!K29+'B S '!K30 -> 354.8 | K27: ='B S '!L28+'B S '!L29+'B S '!L30 -> 163.84 | L27: ='B S '!M28+'B S '!M29+'B S '!M30 -> 131.072
C28: Secured | D28: ='B S '!E28+'B S '!E30 -> 2430 | E28: ='B S '!F28+'B S '!F30 -> 2130 | F28: ='B S '!G28+'B S '!G30 -> 1770 | G28: ='B S '!H28+'B S '!H30 -> 1290 | H28: ='B S '!I28+'B S '!I30 -> 750 | I28: ='B S '!J28+'B S '!J30 -> 150 | J28: ='B S '!K28+'B S '!K30 -> 150 | K28: ='B S '!L28+'B S '!L30 -> 0 | L28: ='B S '!M28+'B S '!M30 -> 0
C29: Unsecured | D29: ='B S '!E29 -> 400 | E29: ='B S '!F29 -> 400 | F29: ='B S '!G29 -> 400 | G29: ='B S '!H29 -> 400 | H29: ='B S '!I29 -> 320 | I29: ='B S '!J29 -> 256 | J29: ='B S '!K29 -> 204.8 | K29: ='B S '!L29 -> 163.84 | L29: ='B S '!M29 -> 131.072
C30: Other investments (excluding investment in allied concerns considered for arriving at net owned funds) | D30: 0 | E30: 0 | F30: 0 | G30: 0 | H30: 0 | I30: 0 | J30: 0 | K30: 0 | L30: 0
C31: Total Assets | D31: =#REF! -> #REF! | E31: =#REF! -> #REF! | F31: =#REF! -> #REF! | G31: =#REF! -> #REF! | H31: =#REF! -> #REF! | I31: =#REF! -> #REF! | J31: =#REF! -> #REF! | K31: =#REF! -> #REF! | L31: =[13]CMA!M192 -> 2230.0314
C32: - Current assets | D32: =#REF! -> #REF! | E32: =#REF! -> #REF! | F32: =#REF! -> #REF! | G32: =#REF! -> #REF! | H32: =#REF! -> #REF! | I32: =#REF! -> #REF! | J32: =#REF! -> #REF! | K32: =#REF! -> #REF! | L32: =[13]CMA!M166 -> 463.14585
C33: - Non-current assets | D33: =#REF! -> #REF! | E33: =#REF! -> #REF! | F33: =#REF! -> #REF! | G33: =#REF! -> #REF! | H33: =#REF! -> #REF! | I33: =#REF! -> #REF! | J33: =#REF! -> #REF! | K33: =#REF! -> #REF! | L33: =[13]CMA!M188 -> 535
C34: Out of which net fixed assets | D34: =#REF! -> #REF! | E34: =#REF! -> #REF! | F34: =#REF! -> #REF! | G34: =#REF! -> #REF! | H34: =#REF! -> #REF! | I34: =#REF! -> #REF! | J34: =#REF! -> #REF! | K34: =#REF! -> #REF! | L34: =[13]CMA!M178 -> 1231.8855
C35: Net working capital * | D35: =#REF! -> #REF! | E35: =#REF! -> #REF! | F35: =#REF! -> #REF! | G35: =#REF! -> #REF! | H35: =#REF! -> #REF! | I35: =#REF! -> #REF! | J35: =#REF! -> #REF! | K35: =#REF! -> #REF! | L35: =[13]CMA!M205 -> 426.58878
C36: Current ratio | D36: =#REF! -> #REF! | E36: =#REF! -> #REF! | F36: =#REF! -> #REF! | G36: =#REF! -> #REF! | H36: =#REF! -> #REF! | I36: =#REF! -> #REF! | J36: =#REF! -> #REF! | K36: =#REF! -> #REF! | L36: =[13]CMA!M203 -> 12.669117
C37: Debt equity ratio | D37: =#REF! -> #REF! | E37: =#REF! -> #REF! | F37: =#REF! -> #REF! | G37: =#REF! -> #REF! | H37: =#REF! -> #REF! | I37: =#REF! -> #REF! | J37: =#REF! -> #REF! | K37: =#REF! -> #REF! | L37: =[13]CMA!M204 -> 0.24341418
C38: Term liability/ Adjusted TNW | D38: =D28/D25 -> #REF! | E38: =E28/E25 -> #REF! | F38: =F28/F25 -> #REF! | G38: =G28/G25 -> #REF! | H38: =H28/H25 -> #REF! | I38: =I28/I25 -> #REF! | J38: =J28/J25 -> #REF! | K38: =K28/K25 -> #REF! | L38: =L27/L25 -> #REF!
C39: TOL/ adjusted TNW | D39: =#REF! -> #REF! | E39: =#REF! -> #REF! | F39: =#REF! -> #REF! | G39: =#REF! -> #REF! | H39: =#REF! -> #REF! | I39: =#REF! -> #REF! | J39: =#REF! -> #REF! | K39: =#REF! -> #REF! | L39: =[13]CMA!M390 -> 0.19902539
C40: Operating profit/ sales | D40: =D11/D9 -> #REF! | E40: =E11/E9 -> #REF! | F40: =F11/F9 -> #REF! | G40: =G11/G9 -> #REF! | H40: =H11/H9 -> #REF! | I40: =I11/I9 -> #REF! | J40: =J11/J9 -> #REF! | K40: =K11/K9 -> #REF! | L40: =L11/L9 -> #REF!
...

Sheet IRR_CASE_II
F2: (34)
E4: ANNEXURE IX
D5: Internal Rate of Return
E6: Rs. In Lakhs
B8: Year | D8: Construction | E8: Year 1 | F8: Year 2 | G8: Year 3 | H8: Year 4 | I8: Year 5 | J8: Year 6 | K8: Year 7 | L8: Year 8 | M8: Year 9
B10: CASH INFLOW | Q10: 0.1304865
B12: Profit After Tax | E12: ='P L _Case_II'!D59 -> 173.26791 | F12: ='P L _Case_II'!E59 -> 259.13865 | G12: ='P L _Case_II'!F59 -> 363.52877 | H12: ='P L _Case_II'!G59 -> 443.49834 | I12: ='P L _Case_II'!H59 -> 437.83929 | J12: ='P L _Case_II'!I59 -> 363.01551 | K12: ='P L _Case_II'!J59 -> 342.952 | L12: ='P L _Case_II'!K59 -> 290.2259 | M12: ='P L _Case_II'!L59 -> #VALUE!
B13: Depreciation | E13: ='P L '!D53 -> 452.19406 | F13: ='P L '!E53 -> 452.19406 | G13: ='P L '!F53 -> 452.19406 | H13: ='P L '!G53 -> 452.19406 | I13: ='P L '!H53 -> 452.19406 | J13: ='P L '!I53 -> 452.19406 | K13: ='P L '!J53 -> 452.19406 | L13: ='P L '!K53 -> 452.19406 | M13: ='P L '!L53 -> 452.19406
B14: Interest on Term Loan | E14: ='P L '!D50 -> 254.71875 | F14: ='P L '!E50 -> 240.1125 | G14: ='P L '!F50 -> 217.7875 | H14: ='P L '!G50 -> 186.675 | I14: ='P L '!H50 -> 147.25 | J14: ='P L '!I50 -> 99.0375 | K14: ='P L '!J50 -> 45.125 | L14: ='P L '!K50 -> 2.375 | M14: ='P L '!L50 -> 0
B15: Residual Value of Fixed Assets | L15: =0.5*'B S '!L13 -> 598.15591 | N15: *
B17: TOTAL CASH INFLOW | D17: =SUM(D10:D15) -> 0 | E17: =SUM(E10:E15) -> 880.18072 | F17: =SUM(F10:F15) -> 951.44521 | G17: =SUM(G10:G15) -> 1033.5103 | H17: =SUM(H10:H15) -> 1082.3674 | I17: =SUM(I10:I15) -> 1037.2833 | J17: =SUM(J10:J15) -> 914.24707 | K17: =SUM(K10:K15) -> 840.27106 | ... M17: =SUM(M10:M15) -> #VALUE!
B19: CASH OUTFLOWS
B21: Capital Expenditure | D21: ='CAPITAL COST'!D36+'CAPITAL COST'!D34 -> 4263.8643 | E21: 0 | F21: 0 | G21: 0 | H21: 0 | I21: 0 | J21: 0 | K21: 0 | L21: 0 | M21: 0
B23: TOTAL CASH OUTFLOW | D23: =SUM(D19:D22) -> 4263.8643 | E23: =SUM(E19:E22) -> 0 | F23: =SUM(F19:F22) -> 0 | G23: =SUM(G19:G22) -> 0 | H23: =SUM(H19:H22) -> 0 | I23: =SUM(I19:I22) -> 0 | J23: =SUM(J19:J22) -> 0 | K23: =SUM(K19:K22) -> 0 | ... M23: =SUM(M19:M22) -> 0
B25: NET CASH FLOW | D25: =D17-D23 -> -4263.8643 | E25: =E17-E23 -> 880.18072 | F25: =F17-F23 -> 951.44521 | G25: =G17-G23 -> 1033.5103 | H25: =H17-H23 -> 1082.3674 | I25: =I17-I23 -> 1037.2833 | J25: =J17-J23 -> 914.24707 | K25: =K17-K23 -> 840.27106 | ... M25: =M17-M23 -> #VALUE!
B27: Discounting Factor | D27: 1 | E27: 1 | F27: =1/(1+Q10) -> 0.88457492 | G27: =+F27/(1+$Q$10) -> 0.78247278 | H27: =+G27/(1+$Q$10) -> 0.69215579 | I27: =+H27/(1+$Q$10) -> 0.61226365 | J27: =+I27/(1+$Q$10) -> 0.54159307 | K27: =+J27/(1+$Q$10) -> 0.47907964 | L27: =+K27/(1+$Q$10) -> 0.42378183 | M27: =+L27/(1+$Q$10) -> 0.37486678
B28: Present Value | D28: =D25*D27 -> -4263.8643 | E28: =E25*E27 -> 880.18072 | F28: =F25*F27 -> 841.62457 | G28: =G25*G27 -> 808.6937 | H28: =H25*H27 -> 749.16687 | I28: =I25*I27 -> 635.09089 | J28: =J25*J27 -> 495.14987 | K28: =K25*K27 -> 402.55676 | ... M28: =M25*M27 -> #VALUE!
B31: Net Present Value (Rs.) | E31: =SUM(D28:L28) -> 1117.7173
B33: The Internal Rate of Return is | E33: =Q10 -> 0.1304865
B36: * Residual value of fixed assets has been considered at 50% of Book WDV

Sheet BEP ANAYSIS_II
F2: (30)
E4: ANNEXURE V
E5: Break Even Analysis
F6: Rs. In Lakhs
B7: Year | D7: Basis | E7: Year 1 | F7: Year 2 | G7: Year 3 | H7: Year 4 | I7: Year 5 | J7: Year 6 | K7: Year 7 | L7: Year 8 | M7: Year 9
B9: Gross Revenue Receipt | E9: ='P L _Case_II'!D25 -> 1475.5014 | F9: ='P L _Case_II'!E25 -> 1721.4183 | G9: ='P L _Case_II'!F25 -> 1967.3352 | H9: ='P L _Case_II'!G25 -> 2213.252 | I9: ='P L _Case_II'!H25 -> 2459.1689 | J9: ='P L _Case_II'!I25 -> 2459.1689 | K9: ='P L _Case_II'!J25 -> 2459.1689 | L9: ='P L _Case_II'!K25 -> 2459.1689 | M9: ='P L _Case_II'!L25 -> 2459.1689
B11: VARIABLE COSTS
B14: TOTAL VARIABLE COSTS | E14: ='P L _Case_II'!D51+'P L _Case_II'!D58-E20 -> #REF! | F14: ='P L _Case_II'!E51+'P L _Case_II'!E58-F20 -> #REF! | G14: ='P L _Case_II'!F51+'P L _Case_II'!F58-G20 -> #REF! | H14: ='P L _Case_II'!G51+'P L _Case_II'!G58-H20 -> #REF! | I14: ='P L _Case_II'!H51+'P L _Case_II'!H58-I20 -> #REF! | J14: ='P L _Case_II'!I51+'P L _Case_II'!I58-J20 -> #REF! | K14: ='P L _Case_II'!J51+'P L _Case_II'!J58-K20 -> #REF! | L14: ='P L _Case_II'!K51+'P L _Case_II'!K58-L20 -> #REF! | M14: ='P L _Case_II'!L51+'P L _Case_II'!L58-M20 -> #VALUE!
B16: CONTRIBUTION | E16: =E9-E14 -> #REF! | F16: =F9-F14 -> #REF! | G16: =G9-G14 -> #REF! | H16: =H9-H14 -> #REF! | I16: =I9-I14 -> #REF! | J16: =J9-J14 -> #REF! | K16: =K9-K14 -> #REF! | L16: =L9-L14 -> #REF! | M16: =M9-M14 -> #VALUE!
B18: FIXED COSTS
B20: TOTAL FIXED COSTS | E20: =#REF! -> #REF! | F20: =#REF! -> #REF! | G20: =#REF! -> #REF! | H20: =#REF! -> #REF! | I20: =#REF! -> #REF! | J20: =#REF! -> #REF! | K20: =#REF! -> #REF! | L20: =#REF! -> #REF! | M20: =#REF! -> #REF!
B22: P/V Ratio | E22: =E16/E9*100 -> #REF! | F22: =F16/F9*100 -> #REF! | G22: =G16/G9*100 -> #REF! | H22: =H16/H9*100 -> #REF! | I22: =I16/I9*100 -> #REF! | J22: =J16/J9*100 -> #REF! | K22: =K16/K9*100 -> #REF! | L22: =L16/L9*100 -> #REF! | M22: =M16/M9*100 -> #VALUE!
B23: Break Even Sales | E23: =+E20/E22*100 -> #REF! | F23: =+F20/F22*100 -> #REF! | G23: =+G20/G22*100 -> #REF! | H23: =+H20/H22*100 -> #REF! | I23: =+I20/I22*100 -> #REF! | J23: =+J20/J22*100 -> #REF! | K23: =+K20/K22*100 -> #REF! | L23: =+L20/L22*100 -> #REF! | M23: =+M20/M22*100 -> #REF!
B24: Break Even Point Room Occupancy Achieved | E24: =+E23/E9*100 -> #REF! | F24: =+F23/F9*100 -> #REF! | G24: =+G23/G9*100 -> #REF! | H24: =+H23/H9*100 -> #REF! | I24: =+I23/I9*100 -> #REF! | J24: =+J23/J9*100 -> #REF! | K24: =+K23/K9*100 -> #REF! | L24: =+L23/L9*100 -> #REF! | M24: =+M23/M9*100 -> #REF!
B25: Average Break Even Point Room Occupancy Achieved | E25: =AVERAGE(E24:L24) -> #REF!
B26: Break Even Point Room Capacity | E26: =E23/SALESPROJECTION!E81*100 -> #REF! | F26: =F23/SALESPROJECTION!F81*100 -> #REF! | G26: =G23/SALESPROJECTION!G81*100 -> #REF! | H26: =H23/SALESPROJECTION!H81*100 -> #REF! | I26: =I23/SALESPROJECTION!I81*100 -> #REF! | J26: =J23/SALESPROJECTION!J81*100 -> #REF! | K26: =K23/SALESPROJECTION!K81*100 -> #REF! | L26: =L23/SALESPROJECTION!L81*100 -> #REF! | M26: =M23/SALESPROJECTION!M81*100 -> #REF!
B27: Average Break Even Point Room Capacity | E27: =AVERAGE(E26:L26) -> #REF!
B28: Cash Break Even Point Room Capacity | E28: =(((E20-('P L _Case_II'!D49*0.75))/E22*100/SALESPROJECTION!E81*100)) -> #REF! | F28: =(((F20-('P L _Case_II'!E49*0.75))/F22*100/SALESPROJECTION!F81*100)) -> #REF! | G28: =(((G20-('P L _Case_II'!F49*0.75))/G22*100/SALESPROJECTION!G81*100)) -> #REF! | H28: =(((H20-('P L _Case_II'!G49*0.75))/H22*100/SALESPROJECTION!H81*100)) -> #REF! | I28: =(((I20-('P L _Case_II'!H49*0.75))/I22*100/SALESPROJECTION!I81*100)) -> #REF! | J28: =(((J20-('P L _Case_II'!I49*0.75))/J22*100/SALESPROJECTION!J81*100)) -> #REF! | K28: =(((K20-('P L _Case_II'!J49*0.75))/K22*100/SALESPROJECTION!K81*100)) -> #REF! | L28: =(((L20-('P L _Case_II'!K49*0.75))/L22*100/SALESPROJECTION!L81*100)) -> #REF! | M28: =(((M20-('P L _Case_II'!L49*0.75))/M22*100/SALESPROJECTION!M81*100)) -> #REF!
B29: Average Cash Break Even Point Room Capacity | E29: =AVERAGE(E28:L28) -> #REF!
E32: =E20+E14 -> #REF! | F32: =F20+F14 -> #REF! | G32: =G20+G14 -> #REF! | H32: =H20+H14 -> #REF! | I32: =I20+I14 -> #REF! | J32: =J20+J14 -> #REF! | K32: =K20+K14 -> #REF! | L32: =L20+L14 -> #REF! | M32: =M20+M14 -> #REF!
E33: =E32-'P L _Case_II'!D51-'P L _Case_II'!D58 -> #REF! | F33: =F32-'P L _Case_II'!E51-'P L _Case_II'!E58 -> #REF! | G33: =G32-'P L _Case_II'!F51-'P L _Case_II'!F58 -> #REF! | H33: =H32-'P L _Case_II'!G51-'P L _Case_II'!G58 -> #REF! | I33: =I32-'P L _Case_II'!H51-'P L _Case_II'!H58 -> #REF! | J33: =J32-'P L _Case_II'!I51-'P L _Case_II'!I58 -> #REF! | K33: =K32-'P L _Case_II'!J51-'P L _Case_II'!J58 -> #REF! | L33: =L32-'P L _Case_II'!K51-'P L _Case_II'!K58 -> #REF! | M33: =M32-'P L _Case_II'!L51-'P L _Case_II'!L58 -> #REF!

Sheet P  L _Case_II
D2: (28)
D4: ANNEXURE III
C5: Projected Profitability
J6: Rs. In Lacs
A8: Year | D8: 1 | E8: 2 | F8: 3 | G8: 4 | H8: 5 | I8: 6 | J8: 7 | K8: 8 | L8: 9
A10: Room Charges | D10: =SALESPROJECTION!E74 -> 3668.25 | E10: =SALESPROJECTION!F74 -> 3668.25 | F10: =SALESPROJECTION!G74 -> 3668.25 | G10: =SALESPROJECTION!H74 -> 3668.25 | H10: =SALESPROJECTION!I74 -> 3668.25 | I10: =SALESPROJECTION!J74 -> 3668.25 | J10: =SALESPROJECTION!K74 -> 3668.25 | K10: =SALESPROJECTION!L74 -> 3668.25 | L10: =SALESPROJECTION!M74 -> 3668.25
A11: F & B Sales | D11: =SALESPROJECTION!E75 -> 884.33569 | E11: =SALESPROJECTION!F75 -> 884.33569 | F11: =SALESPROJECTION!G75 -> 884.33569 | G11: =SALESPROJECTION!H75 -> 884.33569 | H11: =SALESPROJECTION!I75 -> 884.33569 | I11: =SALESPROJECTION!J75 -> 884.33569 | J11: =SALESPROJECTION!K75 -> 884.33569 | K11: =SALESPROJECTION!L75 -> 884.33569 | L11: =SALESPROJECTION!M75 -> 884.33569
A12: Banquet Hall Receipts | D12: =SALESPROJECTION!E76 -> 195 | E12: =SALESPROJECTION!F76 -> 195 | F12: =SALESPROJECTION!G76 -> 195 | G12: =SALESPROJECTION!H76 -> 195 | H12: =SALESPROJECTION!I76 -> 195 | I12: =SALESPROJECTION!J76 -> 195 | J12: =SALESPROJECTION!K76 -> 195 | K12: =SALESPROJECTION!L76 -> 195 | L12: =SALESPROJECTION!M76 -> 195
A13: Conference Hall Receipts | D13: =SALESPROJECTION!E79 -> 45 | E13: =SALESPROJECTION!F79 -> 45 | F13: =SALESPROJECTION!G79 -> 45 | G13: =SALESPROJECTION!H79 -> 45 | H13: =SALESPROJECTION!I79 -> 45 | I13: =SALESPROJECTION!J79 -> 45 | J13: =SALESPROJECTION!K79 -> 45 | K13: =SALESPROJECTION!L79 -> 45 | L13: =SALESPROJECTION!M79 -> 45
A14: Other Income | D14: =SALESPROJECTION!E80 -> 125.7522 | E14: =SALESPROJECTION!F80 -> 125.7522 | F14: =SALESPROJECTION!G80 -> 125.7522 | G14: =SALESPROJECTION!H80 -> 125.7522 | H14: =SALESPROJECTION!I80 -> 125.7522 | I14: =SALESPROJECTION!J80 -> 125.7522 | J14: =SALESPROJECTION!K80 -> 125.7522 | K14: =SALESPROJECTION!L80 -> 125.7522 | L14: =SALESPROJECTION!M80 -> 125.7522
A15: Gross Revenue Receipt | D15: =SUM(D10:D14) -> 4918.3379 | E15: =SUM(E10:E14) -> 4918.3379 | F15: =SUM(F10:F14) -> 4918.3379 | G15: =SUM(G10:G14) -> 4918.3379 | H15: =SUM(H10:H14) -> 4918.3379 | I15: =SUM(I10:I14) -> 4918.3379 | J15: =SUM(J10:J14) -> 4918.3379 | K15: =SUM(K10:K14) -> 4918.3379 | L15: =SUM(L10:L14) -> 4918.3379 | T15: =E15-SALESPROJECTION!F81 -> -111.75 | U15: =F15-SALESPROJECTION!G81 -> -111.75 | V15: =G15-SALESPROJECTION!H81 -> -111.75 | W15: =H15-SALESPROJECTION!I81 -> -111.75 | X15: =I15-SALESPROJECTION!J81 -> -111.75 | Y15: =J15-SALESPROJECTION!K81 -> -111.75
A16: Envisaged Occupancy | D16: =40%-10% -> 0.3 | E16: =D16+0.05 -> 0.35 | F16: =E16+0.05 -> 0.4 | G16: =F16+0.05 -> 0.45 | H16: =G16+5% -> 0.5 | I16: =H16 -> 0.5 | J16: =I16 -> 0.5 | K16: =J16 -> 0.5 | L16: =K16 -> 0.5
A18: Projected Sales
A20: Room Sales | D20: =D16*D10 -> 1100.475 | E20: =E16*E10 -> 1283.8875 | F20: =F16*F10 -> 1467.3 | G20: =G16*G10 -> 1650.7125 | H20: =H16*H10 -> 1834.125 | I20: =I16*I10 -> 1834.125 | J20: =J16*J10 -> 1834.125 | K20: =K16*K10 -> 1834.125 | L20: =L16*L10 -> 1834.125
A21: F & B Sales | D21: =$D$16*D11 -> 265.30071 | E21: =$E$16*E11 -> 309.51749 | F21: =$F$16*F11 -> 353.73428 | G21: =$G$16*G11 -> 397.95106 | H21: =$H$16*H11 -> 442.16784 | I21: =$I$16*I11 -> 442.16784 | J21: =$J$16*J11 -> 442.16784 | K21: =$K$16*K11 -> 442.16784 | L21: =$K$16*L11 -> 442.16784
A22: Banquet Hall Receipts | D22: =$D$16*D12 -> 58.5 | E22: =$E$16*E12 -> 68.25 | F22: =$F$16*F12 -> 78 | G22: =$G$16*G12 -> 87.75 | H22: =$H$16*H12 -> 97.5 | I22: =$I$16*I12 -> 97.5 | J22: =$J$16*J12 -> 97.5 | K22: =$K$16*K12 -> 97.5 | L22: =$K$16*L12 -> 97.5
A23: Conference Hall Receipts | D23: =$D$16*D13 -> 13.5 | E23: =$E$16*E13 -> 15.75 | F23: =$F$16*F13 -> 18 | G23: =$G$16*G13 -> 20.25 | H23: =$H$16*H13 -> 22.5 | I23: =$I$16*I13 -> 22.5 | J23: =$J$16*J13 -> 22.5 | K23: =$K$16*K13 -> 22.5 | L23: =$K$16*L13 -> 22.5
A24: Other Income | D24: =D16*D14 -> 37.725659 | E24: =E16*E14 -> 44.013269 | F24: =F16*F14 -> 50.300879 | G24: =G16*G14 -> 56.588489 | H24: =H16*H14 -> 62.876099 | I24: =I16*I14 -> 62.876099 | J24: =J16*J14 -> 62.876099 | K24: =K16*K14 -> 62.876099 | L24: =L16*L14 -> 62.876099
A25: Total Projected Sales | D25: =SUM(D20:D24) -> 1475.5014 | E25: =SUM(E20:E24) -> 1721.4183 | F25: =SUM(F20:F24) -> 1967.3352 | G25: =SUM(G20:G24) -> 2213.252 | H25: =SUM(H20:H24) -> 2459.1689 | I25: =SUM(I20:I24) -> 2459.1689 | J25: =SUM(J20:J24) -> 2459.1689 | K25: =SUM(K20:K24) -> 2459.1689 | L25: =SUM(L20:L24) -> 2459.1689
A27: Revenue Expenses | B27: As | C27: of
A29: Food & Beverages Cost | B29: 0.4 | C29: F & B sales | D29: =ROUND(B29*D21,2) -> 106.12 | E29: =B29*E21 -> 123.807 | F29: =B29*F21 -> 141.49371 | G29: =B29*G21 -> 159.18042 | H29: =B29*H21 -> 176.86714 | I29: =B29*I21 -> 176.86714 | J29: =$B$29*J21 -> 176.86714 | K29: =$B$29*K21 -> 176.86714 | L29: =$B$29*L21 -> 176.86714
A30: Banquet & Conference Hall Expenses | B30: 0.25 | C30: B & C Receipts | D30: =(D22+D23)*$B$30 -> 18 | E30: =(E22+E23)*$B$30 -> 21 | F30: =(F22+F23)*$B$30 -> 24 | G30: =(G22+G23)*$B$30 -> 27 | H30: =(H22+H23)*$B$30 -> 30 | I30: =(I22+I23)*$B$30 -> 30 | J30: =(J22+J23)*$B$30 -> 30 | K30: =(K22+K23)*$B$30 -> 30 | L30: =(L22+L23)*$B$30 -> 30
A31: Employee Related Expenses | B31: 0.09 | C31: Total Sales | D31: =B31*D25 -> 132.79512 | E31: =B31*E25*1.05 -> 162.67403 | F31: =B31*F25*1.1 -> 194.76618 | G31: =B31*G25*1.2 -> 239.03122 | H31: =B31*H25*1.2 -> 265.59025 | I31: =B31*I25*1.25 -> 276.65651 | J31: =$B$31*J25*1.3 -> 287.72277 | K31: =$B$31*K25*1.35 -> 298.78903 | L31: =$B$31*L25*1.4 -> 309.85529 | P31: Increasing
A32: Power, Fuel & Water Charges | B32: 0.075 | C32: Total Sales | D32: =ROUND(B32*D25,2) -> 110.66 | E32: =B32*E25 -> 129.10637 | F32: =B32*F25 -> 147.55014 | G32: =B32*G25 -> 165.9939 | H32: =B32*H25 -> 184.43767 | I32: =B32*I25 -> 184.43767 | J32: =$B$32*J25 -> 184.43767 | K32: =$B$32*K25 -> 184.43767 | L32: =$B$32*L25 -> 184.43767
A33: Repair & Maintenance | B33: 0.005 | C33: Assets | D33: =depreciation!D147*0.5% -> 19.058351 | E33: =depreciation!E147*1% -> 33.594762 | F33: =depreciation!F147*1.25% -> 37.528526 | G33: =depreciation!G147*2.5% -> 64.002201 | H33: =depreciation!H147*2.5% -> 55.69735 | I33: =depreciation!I147*3% -> 56.570998 | J33: =depreciation!J147*3.5% -> 54.197705 | K33: =depreciation!K147*4% -> 47.852472 | L33: =depreciation!L147*4.75% -> 39.383093 | P33: Increasing
A34: Discount on Room Rentals | B34: 0.05 | C34: Room Sales | D34: =D20*B34 -> 55.02375 | E34: =E20*B34*1.5 -> 96.291563 | F34: =F20*B34*2 -> 146.73 | G34: =G20*B34*2.15 -> 177.45159 | H34: =H20*B34*2.25 -> 206.33906 | I34: =I20*B34*2.5 -> 229.26563 | J34: =J20*$B$34*2.5 -> 229.26563 | K34: =K20*$B$34*2.5 -> 229.26563 | L34: =L20*$B$34*2.5 -> 229.26563 | P34: Increasing | Q34: Max 25%
A35: Room Upkeep Exp. | B35: 0.04 | C35: Room Sales | D35: =B35*D20 -> 44.019 | E35: =B35*E20*1.25 -> 64.194375 | F35: =B35*F20*1.25 -> 73.365 | G35: =B35*G20*1.25 -> 82.535625 | H35: =B35*H20*1.25 -> 91.70625 | I35: =B35*I20*1.25 -> 91.70625 | J35: =B35*J20*1.25 -> 91.70625 | K35: =B35*K20*1.25 -> 91.70625 | L35: =B35*L20*1.25 -> 91.70625 | P35: Increasing | Q35: Normal
A36: General Upkeep & Services | B36: 0.01 | C36: Total Sales | D36: =B36*D25 -> 14.755014 | E36: =B36*E25 -> 17.214183 | F36: =B36*F25*1.1 -> 21.640687 | G36: =B36*G25*1.2 -> 26.559025 | H36: =B36*H25*1.2 -> 29.510027 | I36: =B36*I25*1.2 -> 29.510027 | J36: =B36*J25*1.2 -> 29.510027 | K36: =B36*K25*1.2 -> 29.510027 | L36: =B36*L25*1.2 -> 29.510027 | P36: Increasing | Q36: Normal
A37: Administration Expenses | B37: 0.0225 | C37: Total Sales | D37: =B37*D25 -> 33.198781 | E37: =B37*E25*1.1 -> 42.605102 | F37: =B37*F25*1.1 -> 48.691545 | G37: =B37*G25*1.15 -> 57.267897 | H37: =B37*H25*1.2 -> 66.397561 | I37: =B37*I25*1.25 -> 69.164127 | J37: =B37*J25*1.3 -> 71.930692 | K37: =B37*K25*1.35 -> 74.697257 | L37: =B37*L25*1.4 -> 77.463822 | P37: Increasing
A38: Management expenses | B38: 0.025 | C38: Total Sales | D38: =B38*D25 -> 36.887534 | E38: =B38*E25*1.1 -> 47.339002 | F38: =B38*F25*1.1 -> 54.101717 | G38: =B38*G25*1.25 -> 69.164127 | H38: =B38*H25*1.25 -> 76.849029 | I38: =B38*I25*1.25 -> 76.849029 | J38: =B38*J25*1.25 -> 76.849029 | K38: =B38*K25*1.25 -> 76.849029 | L38: =B38*L25*1.25 -> 76.849029 | P38: Increasing | Q38: Normal
A39: Advertisement & Sales Promotion | B39: 0.0125 | C39: Total Sales | D39: =B39*D25 -> 18.443767 | E39: =B39*E25*1.5 -> 32.276592 | F39: =B39*F25*2 -> 49.183379 | G39: =B39*G25*2.5 -> 69.164127 | H39: =B39*H25*2.75 -> 84.533932 | I39: =B39*I25*3.5 -> 107.58864 | J39: =B39*J25*3.75 -> 115.27354 | K39: =B39*K25*4 -> 122.95845 | L39: =B39*L25*4.25 -> 130.64335 | P39: Increasing
A40: Insurance Charges
A41: Building | B41: 0.0033 | D41: =B41*'CAPITAL COST'!C14 -> 9.5004913 | E41: =D41 -> 9.5004913 | F41: =E41 -> 9.5004913 | G41: =F41 -> 9.5004913 | H41: =G41 -> 9.5004913 | I41: =H41 -> 9.5004913 | J41: =I41 -> 9.5004913 | K41: =J41 -> 9.5004913 | L41: =K41 -> 9.5004913 | V41: =B41*depreciation!D128 -> 10.488325 | W41: =B41*'CAPITAL COST'!D14 -> 9.5004913
A42: Plant & Equipment | B42: 0.005 | D42: =B42*'CAPITAL COST'!D20+(ASSETS!I82-ASSETS!I78+('details of fixed assets '!F145/100000+'details of fixed assets '!F146/100000))*B42 -> 3.6821262 | E42: =D42 -> 3.6821262 | F42: =E42 -> 3.6821262 | G42: =F42 -> 3.6821262 | H42: =G42 -> 3.6821262 | I42: =H42 -> 3.6821262 | J42: =I42 -> 3.6821262 | K42: =J42 -> 3.6821262 | L42: =K42 -> 3.6821262 | W42: =B42*('CAPITAL COST'!D20+'CAPITAL COST'!D16) -> 4.2141962
A43: Furniture & Accessories | B43: 0.0025 | D43: =B43*(SUM('details of fixed assets '!F138:F144))/100000 -> 0.38145 | E43: =D43 -> 0.38145 | F43: =E43 -> 0.38145 | G43: =F43 -> 0.38145 | H43: =G43 -> 0.38145 | I43: =H43 -> 0.38145 | J43: =I43 -> 0.38145 | K43: =J43 -> 0.38145 | L43: =K43 -> 0.38145
A44: Inventory | B44: 0.002 | D44: =+' wORKING CAPITAL'!E15*$B$44 -> 0.024 | E44: =+' wORKING CAPITAL'!F15*$B$44 -> 0.023922285 | F44: =+' wORKING CAPITAL'!G15*$B$44 -> 0.026530071 | G44: =+' wORKING CAPITAL'!H15*$B$44 -> 0.029477856 | H44: =+' wORKING CAPITAL'!I15*$B$44 -> 0.03891077 | I44: =+' wORKING CAPITAL'!J15*$B$44 -> 0.049522799 | J44: =+' wORKING CAPITAL'!K15*$B$44 -> 0.061313941 | K44: =+' wORKING CAPITAL'!L15*$B$44 -> 0.074284198 | L44: =+' wORKING CAPITAL'!M15*$B$44 -> 0.070746855
A45: Brokerage & Commission | B45: 0.005 | C45: Total Sales | D45: =B45*D25 -> 7.3775068 | E45: =B45*E25 -> 8.6070913 | F45: =B45*F25*1.25 -> 12.295845 | G45: =B45*G25*1.75 -> 19.365955 | H45: =B45*H25*2 -> 24.591689 | I45: =B45*I25*2.5 -> 30.739612 | J45: =B45*J25*3 -> 36.887534 | K45: =B45*K25*3.5 -> 43.035456 | L45: =B45*L25*3.6 -> 44.265041 | U45: =MIN(2,#REF!,#REF!,#REF!,#REF!,#REF!,#REF!,#REF!,#REF!) -> #REF!
A46: Interest on Term Loan | D46: =Interest!I58 -> 240.1125 | E46: =Interest!I70 -> 217.7875 | F46: =Interest!I82 -> 186.675 | G46: =Interest!I94 -> 147.25 | H46: =Interest!I106 -> 99.0375 | I46: =Interest!I118 -> 45.125 | J46: =Interest!I130 -> 2.375 | K46: =Interest!I142 -> 0 | L46: =Interest!I154 -> 0
A47: Interest on Working Capital Loan | D47: =' wORKING CAPITAL'!E29 -> 0 | E47: =' wORKING CAPITAL'!F29 -> 0 | F47: =' wORKING CAPITAL'!G29 -> 0 | G47: =' wORKING CAPITAL'!H29 -> 0 | H47: =' wORKING CAPITAL'!I29 -> 0 | I47: =' wORKING CAPITAL'!J29 -> 0 | J47: =' wORKING CAPITAL'!K29 -> 0 | K47: =' wORKING CAPITAL'!L29 -> 0 | L47: =' wORKING CAPITAL'!M29 -> 0
A49: Depreciation | D49: =depreciation!D139 -> 452.19406 | E49: =depreciation!E139 -> 452.19406 | F49: =depreciation!F139 -> 452.19406 | G49: =depreciation!G139 -> 452.19406 | H49: =depreciation!H139 -> 452.19406 | I49: =depreciation!I139 -> 452.19406 | J49: =depreciation!J139 -> 452.19406 | K49: =depreciation!K139 -> 452.19406 | L49: =depreciation!L139 -> 452.19406
...

Sheet IRR_CASE_III
F2: (34)
E4: ANNEXURE IX
D5: Internal Rate of Return
E6: Rs. In Lakhs
B8: Year | D8: Construction | E8: Year 1 | F8: Year 2 | G8: Year 3 | H8: Year 4 | I8: Year 5 | J8: Year 6 | K8: Year 7 | L8: Year 8 | M8: Year 9
B10: CASH INFLOW | Q10: 0.150178
B12: Profit After Tax | E12: ='P L _Case_III'!D59 -> 374.30812 | F12: ='P L _Case_III'!E59 -> 427.41975 | G12: ='P L _Case_III'!F59 -> 374.79916 | H12: ='P L _Case_III'!G59 -> 397.07843 | I12: ='P L _Case_III'!H59 -> 505.82163 | J12: ='P L _Case_III'!I59 -> 446.74223 | K12: ='P L _Case_III'!J59 -> 421.1456 | L12: ='P L _Case_III'!K59 -> 362.88636 | M12: ='P L _Case_III'!L59 -> #VALUE!
B13: Depreciation | E13: ='P L '!D53 -> 452.19406 | F13: ='P L '!E53 -> 452.19406 | G13: ='P L '!F53 -> 452.19406 | H13: ='P L '!G53 -> 452.19406 | I13: ='P L '!H53 -> 452.19406 | J13: ='P L '!I53 -> 452.19406 | K13: ='P L '!J53 -> 452.19406 | L13: ='P L '!K53 -> 452.19406 | M13: ='P L '!L53 -> 452.19406
B14: Interest on Term Loan | E14: ='P L '!D50 -> 254.71875 | F14: ='P L '!E50 -> 240.1125 | G14: ='P L '!F50 -> 217.7875 | H14: ='P L '!G50 -> 186.675 | I14: ='P L '!H50 -> 147.25 | J14: ='P L '!I50 -> 99.0375 | K14: ='P L '!J50 -> 45.125 | L14: ='P L '!K50 -> 2.375 | M14: ='P L '!L50 -> 0
B15: Residual Value of Fixed Assets | L15: =0.5*'B S '!L13 -> 598.15591 | N15: *
B17: TOTAL CASH INFLOW | D17: =SUM(D10:D15) -> 0 | E17: =SUM(E10:E15) -> 1081.2209 | F17: =SUM(F10:F15) -> 1119.7263 | G17: =SUM(G10:G15) -> 1044.7807 | H17: =SUM(H10:H15) -> 1035.9475 | I17: =SUM(I10:I15) -> 1105.2657 | J17: =SUM(J10:J15) -> 997.97379 | K17: =SUM(K10:K15) -> 918.46465 | ... M17: =SUM(M10:M15) -> #VALUE!
B19: CASH OUTFLOWS
B21: Capital Expenditure | D21: ='CAPITAL COST'!D36+'CAPITAL COST'!D34 -> 4263.8643 | E21: 0 | F21: 0 | G21: 0 | H21: 0 | I21: 0 | J21: 0 | K21: 0 | L21: 0 | M21: 0
B23: TOTAL CASH OUTFLOW | D23: =SUM(D19:D22) -> 4263.8643 | E23: =SUM(E19:E22) -> 0 | F23: =SUM(F19:F22) -> 0 | G23: =SUM(G19:G22) -> 0 | H23: =SUM(H19:H22) -> 0 | I23: =SUM(I19:I22) -> 0 | J23: =SUM(J19:J22) -> 0 | K23: =SUM(K19:K22) -> 0 | ... M23: =SUM(M19:M22) -> 0
B25: NET CASH FLOW | D25: =D17-D23 -> -4263.8643 | E25: =E17-E23 -> 1081.2209 | F25: =F17-F23 -> 1119.7263 | G25: =G17-G23 -> 1044.7807 | H25: =H17-H23 -> 1035.9475 | I25: =I17-I23 -> 1105.2657 | J25: =J17-J23 -> 997.97379 | K25: =K17-K23 -> 918.46465 | ... M25: =M17-M23 -> #VALUE!
B27: Discounting Factor | D27: 1 | E27: 1 | F27: =1/(1+Q10) -> 0.86943064 | G27: =+F27/(1+$Q$10) -> 0.75590965 | H27: =+G27/(1+$Q$10) -> 0.65721101 | I27: =+H27/(1+$Q$10) -> 0.57139939 | J27: =+I27/(1+$Q$10) -> 0.49679214 | K27: =+J27/(1+$Q$10) -> 0.43192631 | L27: =+K27/(1+$Q$10) -> 0.37552997 | M27: =+L27/(1+$Q$10) -> 0.32649727
B28: Present Value | D28: =D25*D27 -> -4263.8643 | E28: =E25*E27 -> 1081.2209 | F28: =F25*F27 -> 973.52437 | G28: =G25*G27 -> 789.75983 | H28: =H25*H27 -> 680.83609 | I28: =I25*I27 -> 631.54814 | J28: =J25*J27 -> 495.78554 | K28: =K25*K27 -> 396.70905 | ... M28: =M25*M27 -> #VALUE!
B31: Net Present Value (Rs.) | E31: =SUM(D28:L28) -> 1317.1241
B33: The Internal Rate of Return is | E33: =Q10 -> 0.150178
B36: * Residual value of fixed assets has been considered at 50% of Book WDV

Sheet P  L _Case_III
D2: (28)
D4: ANNEXURE III
C5: Projected Profitability
J6: Rs. In Lacs
A8: Year | D8: 1 | E8: 2 | F8: 3 | G8: 4 | H8: 5 | I8: 6 | J8: 7 | K8: 8 | L8: 9
A10: Room Charges | D10: =SALESPROJECTION!E74 -> 3668.25 | E10: =SALESPROJECTION!F74 -> 3668.25 | F10: =SALESPROJECTION!G74 -> 3668.25 | G10: =SALESPROJECTION!H74 -> 3668.25 | H10: =SALESPROJECTION!I74 -> 3668.25 | I10: =SALESPROJECTION!J74 -> 3668.25 | J10: =SALESPROJECTION!K74 -> 3668.25 | K10: =SALESPROJECTION!L74 -> 3668.25 | L10: =SALESPROJECTION!M74 -> 3668.25
A11: F & B Sales | D11: =SALESPROJECTION!E75 -> 884.33569 | E11: =SALESPROJECTION!F75 -> 884.33569 | F11: =SALESPROJECTION!G75 -> 884.33569 | G11: =SALESPROJECTION!H75 -> 884.33569 | H11: =SALESPROJECTION!I75 -> 884.33569 | I11: =SALESPROJECTION!J75 -> 884.33569 | J11: =SALESPROJECTION!K75 -> 884.33569 | K11: =SALESPROJECTION!L75 -> 884.33569 | L11: =SALESPROJECTION!M75 -> 884.33569
A12: Banquet Hall Receipts | D12: =SALESPROJECTION!E76 -> 195 | E12: =SALESPROJECTION!F76 -> 195 | F12: =SALESPROJECTION!G76 -> 195 | G12: =SALESPROJECTION!H76 -> 195 | H12: =SALESPROJECTION!I76 -> 195 | I12: =SALESPROJECTION!J76 -> 195 | J12: =SALESPROJECTION!K76 -> 195 | K12: =SALESPROJECTION!L76 -> 195 | L12: =SALESPROJECTION!M76 -> 195
A13: Conference Hall Receipts | D13: =SALESPROJECTION!E79 -> 45 | E13: =SALESPROJECTION!F79 -> 45 | F13: =SALESPROJECTION!G79 -> 45 | G13: =SALESPROJECTION!H79 -> 45 | H13: =SALESPROJECTION!I79 -> 45 | I13: =SALESPROJECTION!J79 -> 45 | J13: =SALESPROJECTION!K79 -> 45 | K13: =SALESPROJECTION!L79 -> 45 | L13: =SALESPROJECTION!M79 -> 45
A14: Other Income | D14: =SALESPROJECTION!E80 -> 125.7522 | E14: =SALESPROJECTION!F80 -> 125.7522 | F14: =SALESPROJECTION!G80 -> 125.7522 | G14: =SALESPROJECTION!H80 -> 125.7522 | H14: =SALESPROJECTION!I80 -> 125.7522 | I14: =SALESPROJECTION!J80 -> 125.7522 | J14: =SALESPROJECTION!K80 -> 125.7522 | K14: =SALESPROJECTION!L80 -> 125.7522 | L14: =SALESPROJECTION!M80 -> 125.7522
A15: Gross Revenue Receipt | D15: =SUM(D10:D14) -> 4918.3379 | E15: =SUM(E10:E14) -> 4918.3379 | F15: =SUM(F10:F14) -> 4918.3379 | G15: =SUM(G10:G14) -> 4918.3379 | H15: =SUM(H10:H14) -> 4918.3379 | I15: =SUM(I10:I14) -> 4918.3379 | J15: =SUM(J10:J14) -> 4918.3379 | K15: =SUM(K10:K14) -> 4918.3379 | L15: =SUM(L10:L14) -> 4918.3379 | T15: =E15-SALESPROJECTION!F81 -> -111.75 | U15: =F15-SALESPROJECTION!G81 -> -111.75 | V15: =G15-SALESPROJECTION!H81 -> -111.75 | W15: =H15-SALESPROJECTION!I81 -> -111.75 | X15: =I15-SALESPROJECTION!J81 -> -111.75 | Y15: =J15-SALESPROJECTION!K81 -> -111.75
A16: Envisaged Occupancy | D16: =40% -> 0.4 | E16: =D16+0.05 -> 0.45 | F16: =E16+0.05 -> 0.5 | G16: =F16+0.05 -> 0.55 | H16: =G16+5% -> 0.6 | I16: =H16 -> 0.6 | J16: =I16 -> 0.6 | K16: =J16 -> 0.6 | L16: =K16 -> 0.6
A18: Projected Sales
A20: Room Sales | D20: =D16*D10 -> 1467.3 | E20: =E16*E10 -> 1650.7125 | F20: =F16*F10 -> 1834.125 | G20: =G16*G10 -> 2017.5375 | H20: =H16*H10 -> 2200.95 | I20: =I16*I10 -> 2200.95 | J20: =J16*J10 -> 2200.95 | K20: =K16*K10 -> 2200.95 | L20: =L16*L10 -> 2200.95
A21: F & B Sales | D21: =$D$16*D11 -> 353.73428 | E21: =$E$16*E11 -> 397.95106 | F21: =$F$16*F11 -> 442.16784 | G21: =$G$16*G11 -> 486.38463 | H21: =$H$16*H11 -> 530.60141 | I21: =$I$16*I11 -> 530.60141 | J21: =$J$16*J11 -> 530.60141 | K21: =$K$16*K11 -> 530.60141 | L21: =$K$16*L11 -> 530.60141
A22: Banquet Hall Receipts | D22: =$D$16*D12 -> 78 | E22: =$E$16*E12 -> 87.75 | F22: =$F$16*F12 -> 97.5 | G22: =$G$16*G12 -> 107.25 | H22: =$H$16*H12 -> 117 | I22: =$I$16*I12 -> 117 | J22: =$J$16*J12 -> 117 | K22: =$K$16*K12 -> 117 | L22: =$K$16*L12 -> 117
A23: Conference Hall Receipts | D23: =$D$16*D13 -> 18 | E23: =$E$16*E13 -> 20.25 | F23: =$F$16*F13 -> 22.5 | G23: =$G$16*G13 -> 24.75 | H23: =$H$16*H13 -> 27 | I23: =$I$16*I13 -> 27 | J23: =$J$16*J13 -> 27 | K23: =$K$16*K13 -> 27 | L23: =$K$16*L13 -> 27
A24: Other Income | D24: =D16*D14 -> 50.300879 | E24: =E16*E14 -> 56.588489 | F24: =F16*F14 -> 62.876099 | G24: =G16*G14 -> 69.163708 | H24: =H16*H14 -> 75.451318 | I24: =I16*I14 -> 75.451318 | J24: =J16*J14 -> 75.451318 | K24: =K16*K14 -> 75.451318 | L24: =L16*L14 -> 75.451318
A25: Total Projected Sales | D25: =SUM(D20:D24) -> 1967.3352 | E25: =SUM(E20:E24) -> 2213.252 | F25: =SUM(F20:F24) -> 2459.1689 | G25: =SUM(G20:G24) -> 2705.0858 | H25: =SUM(H20:H24) -> 2951.0027 | I25: =SUM(I20:I24) -> 2951.0027 | J25: =SUM(J20:J24) -> 2951.0027 | K25: =SUM(K20:K24) -> 2951.0027 | L25: =SUM(L20:L24) -> 2951.0027
A27: Revenue Expenses | B27: As | C27: of
A29: Food & Beverages Cost | B29: 0.4 | C29: F & B sales | D29: =ROUND(B29*D21,2) -> 141.49 | E29: =B29*E21 -> 159.18042 | F29: =B29*F21 -> 176.86714 | G29: =B29*G21 -> 194.55385 | H29: =B29*H21 -> 212.24057 | I29: =B29*I21 -> 212.24057 | J29: =$B$29*J21 -> 212.24057 | K29: =$B$29*K21 -> 212.24057 | L29: =$B$29*L21 -> 212.24057
A30: Banquet & Conference Hall Expenses | B30: 0.25 | C30: B & C Receipts | D30: =(D22+D23)*$B$30 -> 24 | E30: =(E22+E23)*$B$30 -> 27 | F30: =(F22+F23)*$B$30 -> 30 | G30: =(G22+G23)*$B$30 -> 33 | H30: =(H22+H23)*$B$30 -> 36 | I30: =(I22+I23)*$B$30 -> 36 | J30: =(J22+J23)*$B$30 -> 36 | K30: =(K22+K23)*$B$30 -> 36 | L30: =(L22+L23)*$B$30 -> 36
A31: Employee Related Expenses | B31: 0.09 | C31: Total Sales | D31: =B31*D25 -> 177.06016 | E31: =B31*E25*1.05 -> 209.15232 | F31: =B31*F25*1.1 -> 243.45773 | G31: =B31*G25*1.2 -> 292.14927 | H31: =B31*H25*1.2 -> 318.70829 | I31: =B31*I25*1.25 -> 331.98781 | J31: =$B$31*J25*1.3 -> 345.26732 | K31: =$B$31*K25*1.35 -> 358.54683 | L31: =$B$31*L25*1.4 -> 371.82634 | P31: Increasing
A32: Power, Fuel & Water Charges | B32: 0.075 | C32: Total Sales | D32: =ROUND(B32*D25,2) -> 147.55 | E32: =B32*E25 -> 165.9939 | F32: =B32*F25 -> 184.43767 | G32: =B32*G25 -> 202.88144 | H32: =B32*H25 -> 221.3252 | I32: =B32*I25 -> 221.3252 | J32: =$B$32*J25 -> 221.3252 | K32: =$B$32*K25 -> 221.3252 | L32: =$B$32*L25 -> 221.3252
A33: Repair & Maintenance | B33: 0.005 | C33: Assets | D33: =depreciation!D147*0.5% -> 19.058351 | E33: =depreciation!E147*1% -> 33.594762 | F33: =depreciation!F147*1.25% -> 37.528526 | G33: =depreciation!G147*2.5% -> 64.002201 | H33: =depreciation!H147*2.5% -> 55.69735 | I33: =depreciation!I147*3% -> 56.570998 | J33: =depreciation!J147*3.5% -> 54.197705 | K33: =depreciation!K147*4% -> 47.852472 | L33: =depreciation!L147*4.75% -> 39.383093 | P33: Increasing
A34: Discount on Room Rentals | B34: 0.05 | C34: Room Sales | D34: =D20*B34 -> 73.365 | E34: =E20*B34*1.5 -> 123.80344 | F34: =F20*B34*2 -> 183.4125 | G34: =G20*B34*2.15 -> 216.88528 | H34: =H20*B34*2.25 -> 247.60688 | I34: =I20*B34*2.5 -> 275.11875 | J34: =J20*$B$34*2.5 -> 275.11875 | K34: =K20*$B$34*2.5 -> 275.11875 | L34: =L20*$B$34*2.5 -> 275.11875 | P34: Increasing | Q34: Max 25%
A35: Room Upkeep Exp. | B35: 0.04 | C35: Room Sales | D35: =B35*D20 -> 58.692 | E35: =B35*E20*1.25 -> 82.535625 | F35: =B35*F20*1.25 -> 91.70625 | G35: =B35*G20*1.25 -> 100.87688 | H35: =B35*H20*1.25 -> 110.0475 | I35: =B35*I20*1.25 -> 110.0475 | J35: =B35*J20*1.25 -> 110.0475 | K35: =B35*K20*1.25 -> 110.0475 | L35: =B35*L20*1.25 -> 110.0475 | P35: Increasing | Q35: Normal
A36: General Upkeep & Services | B36: 0.01 | C36: Total Sales | D36: =B36*D25 -> 19.673352 | E36: =B36*E25 -> 22.13252 | F36: =B36*F25*1.1 -> 27.050858 | G36: =B36*G25*1.2 -> 32.46103 | H36: =B36*H25*1.2 -> 35.412033 | I36: =B36*I25*1.2 -> 35.412033 | J36: =B36*J25*1.2 -> 35.412033 | K36: =B36*K25*1.2 -> 35.412033 | L36: =B36*L25*1.2 -> 35.412033 | P36: Increasing | Q36: Normal
A37: Administration Expenses | B37: 0.0225 | C37: Total Sales | D37: =B37*D25 -> 44.265041 | E37: =B37*E25*1.1 -> 54.777988 | F37: =B37*F25*1.1 -> 60.864431 | G37: =B37*G25*1.15 -> 69.994096 | H37: =B37*H25*1.2 -> 79.677074 | I37: =B37*I25*1.25 -> 82.996952 | J37: =B37*J25*1.3 -> 86.31683 | K37: =B37*K25*1.35 -> 89.636708 | L37: =B37*L25*1.4 -> 92.956586 | P37: Increasing
A38: Management expenses | B38: 0.025 | C38: Total Sales | D38: =B38*D25 -> 49.183379 | E38: =B38*E25*1.1 -> 60.864431 | F38: =B38*F25*1.1 -> 67.627146 | G38: =B38*G25*1.25 -> 84.533932 | H38: =B38*H25*1.25 -> 92.218835 | I38: =B38*I25*1.25 -> 92.218835 | J38: =B38*J25*1.25 -> 92.218835 | K38: =B38*K25*1.25 -> 92.218835 | L38: =B38*L25*1.25 -> 92.218835 | P38: Increasing | Q38: Normal
A39: Advertisement & Sales Promotion | B39: 0.0125 | C39: Total Sales | D39: =B39*D25 -> 24.591689 | E39: =B39*E25*1.5 -> 41.498476 | F39: =B39*F25*2 -> 61.479224 | G39: =B39*G25*2.5 -> 84.533932 | H39: =B39*H25*2.75 -> 101.44072 | I39: =B39*I25*3.5 -> 129.10637 | J39: =B39*J25*3.75 -> 138.32825 | K39: =B39*K25*4 -> 147.55014 | L39: =B39*L25*4.25 -> 156.77202 | P39: Increasing
A40: Insurance Charges
A41: Building | B41: 0.0033 | D41: =B41*'CAPITAL COST'!C14 -> 9.5004913 | E41: =D41 -> 9.5004913 | F41: =E41 -> 9.5004913 | G41: =F41 -> 9.5004913 | H41: =G41 -> 9.5004913 | I41: =H41 -> 9.5004913 | J41: =I41 -> 9.5004913 | K41: =J41 -> 9.5004913 | L41: =K41 -> 9.5004913 | V41: =B41*depreciation!D128 -> 10.488325 | W41: =B41*'CAPITAL COST'!D14 -> 9.5004913
A42: Plant & Equipment | B42: 0.005 | D42: =B42*'CAPITAL COST'!D20+(ASSETS!I82-ASSETS!I78+('details of fixed assets '!F145/100000+'details of fixed assets '!F146/100000))*B42 -> 3.6821262 | E42: =D42 -> 3.6821262 | F42: =E42 -> 3.6821262 | G42: =F42 -> 3.6821262 | H42: =G42 -> 3.6821262 | I42: =H42 -> 3.6821262 | J42: =I42 -> 3.6821262 | K42: =J42 -> 3.6821262 | L42: =K42 -> 3.6821262 | W42: =B42*('CAPITAL COST'!D20+'CAPITAL COST'!D16) -> 4.2141962
A43: Furniture & Accessories | B43: 0.0025 | D43: =B43*(SUM('details of fixed assets '!F138:F144))/100000 -> 0.38145 | E43: =D43 -> 0.38145 | F43: =E43 -> 0.38145 | G43: =F43 -> 0.38145 | H43: =G43 -> 0.38145 | I43: =H43 -> 0.38145 | J43: =I43 -> 0.38145 | K43: =J43 -> 0.38145 | L43: =K43 -> 0.38145
A44: Inventory | B44: 0.002 | D44: =+' wORKING CAPITAL'!E15*$B$44 -> 0.024 | E44: =+' wORKING CAPITAL'!F15*$B$44 -> 0.023922285 | F44: =+' wORKING CAPITAL'!G15*$B$44 -> 0.026530071 | G44: =+' wORKING CAPITAL'!H15*$B$44 -> 0.029477856 | H44: =+' wORKING CAPITAL'!I15*$B$44 -> 0.03891077 | I44: =+' wORKING CAPITAL'!J15*$B$44 -> 0.049522799 | J44: =+' wORKING CAPITAL'!K15*$B$44 -> 0.061313941 | K44: =+' wORKING CAPITAL'!L15*$B$44 -> 0.074284198 | L44: =+' wORKING CAPITAL'!M15*$B$44 -> 0.070746855
A45: Brokerage & Commission | B45: 0.005 | C45: Total Sales | D45: =B45*D25 -> 9.8366758 | E45: =B45*E25 -> 11.06626 | F45: =B45*F25*1.25 -> 15.369806 | G45: =B45*G25*1.75 -> 23.669501 | H45: =B45*H25*2 -> 29.510027 | I45: =B45*I25*2.5 -> 36.887534 | J45: =B45*J25*3 -> 44.265041 | K45: =B45*K25*3.5 -> 51.642548 | L45: =B45*L25*3.6 -> 53.118049 | U45: =MIN(2,#REF!,#REF!,#REF!,#REF!,#REF!,#REF!,#REF!,#REF!) -> #REF!
A46: Interest on Term Loan | D46: =Interest!I58 -> 240.1125 | E46: =Interest!I70 -> 217.7875 | F46: =Interest!I82 -> 186.675 | G46: =Interest!I94 -> 147.25 | H46: =Interest!I106 -> 99.0375 | I46: =Interest!I118 -> 45.125 | J46: =Interest!I130 -> 2.375 | K46: =Interest!I142 -> 0 | L46: =Interest!I154 -> 0
A47: Interest on Working Capital Loan | D47: =' wORKING CAPITAL'!E29 -> 0 | E47: =' wORKING CAPITAL'!F29 -> 0 | F47: =' wORKING CAPITAL'!G29 -> 0 | G47: =' wORKING CAPITAL'!H29 -> 0 | H47: =' wORKING CAPITAL'!I29 -> 0 | I47: =' wORKING CAPITAL'!J29 -> 0 | J47: =' wORKING CAPITAL'!K29 -> 0 | K47: =' wORKING CAPITAL'!L29 -> 0 | L47: =' wORKING CAPITAL'!M29 -> 0
A49: Depreciation | D49: =depreciation!D139 -> 452.19406 | E49: =depreciation!E139 -> 452.19406 | F49: =depreciation!F139 -> 452.19406 | G49: =depreciation!G139 -> 452.19406 | H49: =depreciation!H139 -> 452.19406 | I49: =depreciation!I139 -> 452.19406 | J49: =depreciation!J139 -> 452.19406 | K49: =depreciation!K139 -> 452.19406 | L49: =depreciation!L139 -> 452.19406
...

Sheet BEP ANAYSIS_IV
F2: (30)
E4: ANNEXURE V
E5: Break Even Analysis
F6: Rs. In Lakhs
B7: Year | D7: Basis | E7: Year 1 | F7: Year 2 | G7: Year 3 | H7: Year 4 | I7: Year 5 | J7: Year 6 | K7: Year 7 | L7: Year 8 | M7: Year 9
B9: Gross Revenue Receipt | E9: ='P L _Case_IV'!D25 -> 1967.3352 | F9: ='P L _Case_IV'!E25 -> 2213.252 | G9: ='P L _Case_IV'!F25 -> 2459.1689 | H9: ='P L _Case_IV'!G25 -> 2705.0858 | I9: ='P L _Case_IV'!H25 -> 2951.0027 | J9: ='P L _Case_IV'!I25 -> 2951.0027 | K9: ='P L _Case_IV'!J25 -> 2951.0027 | L9: ='P L _Case_IV'!K25 -> 2951.0027 | M9: ='P L _Case_IV'!L25 -> 2951.0027
B11: VARIABLE COSTS
B14: TOTAL VARIABLE COSTS | E14: ='P L _Case_IV'!D51+'P L _Case_IV'!D58-E20 -> #REF! | F14: ='P L _Case_IV'!E51+'P L _Case_IV'!E58-F20 -> #REF! | G14: ='P L _Case_IV'!F51+'P L _Case_IV'!F58-G20 -> #REF! | H14: ='P L _Case_IV'!G51+'P L _Case_IV'!G58-H20 -> #REF! | I14: ='P L _Case_IV'!H51+'P L _Case_IV'!H58-I20 -> #REF! | J14: ='P L _Case_IV'!I51+'P L _Case_IV'!I58-J20 -> #REF! | K14: ='P L _Case_IV'!J51+'P L _Case_IV'!J58-K20 -> #REF! | L14: ='P L _Case_IV'!K51+'P L _Case_IV'!K58-L20 -> #REF! | M14: ='P L _Case_IV'!L51+'P L _Case_IV'!L58-M20 -> #VALUE!
B16: CONTRIBUTION | E16: =E9-E14 -> #REF! | F16: =F9-F14 -> #REF! | G16: =G9-G14 -> #REF! | H16: =H9-H14 -> #REF! | I16: =I9-I14 -> #REF! | J16: =J9-J14 -> #REF! | K16: =K9-K14 -> #REF! | L16: =L9-L14 -> #REF! | M16: =M9-M14 -> #VALUE!
B18: FIXED COSTS
B20: TOTAL FIXED COSTS | E20: =#REF! -> #REF! | F20: =#REF! -> #REF! | G20: =#REF! -> #REF! | H20: =#REF! -> #REF! | I20: =#REF! -> #REF! | J20: =#REF! -> #REF! | K20: =#REF! -> #REF! | L20: =#REF! -> #REF! | M20: =#REF! -> #REF!
B22: P/V Ratio | E22: =E16/E9*100 -> #REF! | F22: =F16/F9*100 -> #REF! | G22: =G16/G9*100 -> #REF! | H22: =H16/H9*100 -> #REF! | I22: =I16/I9*100 -> #REF! | J22: =J16/J9*100 -> #REF! | K22: =K16/K9*100 -> #REF! | L22: =L16/L9*100 -> #REF! | M22: =M16/M9*100 -> #VALUE!
B23: Break Even Sales | E23: =+E20/E22*100 -> #REF! | F23: =+F20/F22*100 -> #REF! | G23: =+G20/G22*100 -> #REF! | H23: =+H20/H22*100 -> #REF! | I23: =+I20/I22*100 -> #REF! | J23: =+J20/J22*100 -> #REF! | K23: =+K20/K22*100 -> #REF! | L23: =+L20/L22*100 -> #REF! | M23: =+M20/M22*100 -> #REF!
B24: Break Even Point Room Occupancy Achieved | E24: =+E23/E9*100 -> #REF! | F24: =+F23/F9*100 -> #REF! | G24: =+G23/G9*100 -> #REF! | H24: =+H23/H9*100 -> #REF! | I24: =+I23/I9*100 -> #REF! | J24: =+J23/J9*100 -> #REF! | K24: =+K23/K9*100 -> #REF! | L24: =+L23/L9*100 -> #REF! | M24: =+M23/M9*100 -> #REF!
B25: Average Break Even Point Room Occupancy Achieved | E25: =AVERAGE(E24:L24) -> #REF!
B26: Break Even Point Room Capacity | E26: =E23/SALESPROJECTION!E81*100 -> #REF! | F26: =F23/SALESPROJECTION!F81*100 -> #REF! | G26: =G23/SALESPROJECTION!G81*100 -> #REF! | H26: =H23/SALESPROJECTION!H81*100 -> #REF! | I26: =I23/SALESPROJECTION!I81*100 -> #REF! | J26: =J23/SALESPROJECTION!J81*100 -> #REF! | K26: =K23/SALESPROJECTION!K81*100 -> #REF! | L26: =L23/SALESPROJECTION!L81*100 -> #REF! | M26: =M23/SALESPROJECTION!M81*100 -> #REF!
B27: Average Break Even Point Room Capacity | E27: =AVERAGE(E26:L26) -> #REF!
B28: Cash Break Even Point Room Capacity | E28: =(((E20-('P L _Case_II'!D49*0.75))/E22*100/SALESPROJECTION!E81*100)) -> #REF! | F28: =(((F20-('P L _Case_II'!E49*0.75))/F22*100/SALESPROJECTION!F81*100)) -> #REF! | G28: =(((G20-('P L _Case_II'!F49*0.75))/G22*100/SALESPROJECTION!G81*100)) -> #REF! | H28: =(((H20-('P L _Case_II'!G49*0.75))/H22*100/SALESPROJECTION!H81*100)) -> #REF! | I28: =(((I20-('P L _Case_II'!H49*0.75))/I22*100/SALESPROJECTION!I81*100)) -> #REF! | J28: =(((J20-('P L _Case_II'!I49*0.75))/J22*100/SALESPROJECTION!J81*100)) -> #REF! | K28: =(((K20-('P L _Case_II'!J49*0.75))/K22*100/SALESPROJECTION!K81*100)) -> #REF! | L28: =(((L20-('P L _Case_II'!K49*0.75))/L22*100/SALESPROJECTION!L81*100)) -> #REF! | M28: =(((M20-('P L _Case_II'!L49*0.75))/M22*100/SALESPROJECTION!M81*100)) -> #REF!
B29: Average Cash Break Even Point Room Capacity | E29: =AVERAGE(E28:L28) -> #REF!
E32: =E20+E14 -> #REF! | F32: =F20+F14 -> #REF! | G32: =G20+G14 -> #REF! | H32: =H20+H14 -> #REF! | I32: =I20+I14 -> #REF! | J32: =J20+J14 -> #REF! | K32: =K20+K14 -> #REF! | L32: =L20+L14 -> #REF! | M32: =M20+M14 -> #REF!
E33: =E32-'P L _Case_IV'!D51-'P L _Case_IV'!D58 -> #REF! | F33: =F32-'P L _Case_IV'!E51-'P L _Case_IV'!E58 -> #REF! | G33: =G32-'P L _Case_IV'!F51-'P L _Case_IV'!F58 -> #REF! | H33: =H32-'P L _Case_IV'!G51-'P L _Case_IV'!G58 -> #REF! | I33: =I32-'P L _Case_IV'!H51-'P L _Case_IV'!H58 -> #REF! | J33: =J32-'P L _Case_IV'!I51-'P L _Case_IV'!I58 -> #REF! | K33: =K32-'P L _Case_IV'!J51-'P L _Case_IV'!J58 -> #REF! | L33: =L32-'P L _Case_IV'!K51-'P L _Case_IV'!K58 -> #REF! | M33: =M32-'P L _Case_IV'!L51-'P L _Case_IV'!L58 -> #REF!

Sheet IRR_CASE_IV
F2: (34)
E4: ANNEXURE IX
D5: Internal Rate of Return
E6: Rs. In Lakhs
B8: Year | D8: Construction | E8: Year 1 | F8: Year 2 | G8: Year 3 | H8: Year 4 | I8: Year 5 | J8: Year 6 | K8: Year 7 | L8: Year 8 | M8: Year 9
B10: CASH INFLOW | Q10: 0.12266
B12: Profit After Tax | E12: ='P L _Case_IV'!D59 -> 275.94136 | F12: ='P L _Case_IV'!E59 -> 316.75715 | G12: ='P L _Case_IV'!F59 -> 380.99112 | H12: ='P L _Case_IV'!G59 -> 421.99824 | I12: ='P L _Case_IV'!H59 -> 396.85388 | J12: ='P L _Case_IV'!I59 -> 299.1921 | K12: ='P L _Case_IV'!J59 -> 273.59546 | L12: ='P L _Case_IV'!K59 -> 215.33623 | M12: ='P L _Case_IV'!L59 -> #VALUE!
B13: Depreciation | E13: ='P L '!D53 -> 452.19406 | F13: ='P L '!E53 -> 452.19406 | G13: ='P L '!F53 -> 452.19406 | H13: ='P L '!G53 -> 452.19406 | I13: ='P L '!H53 -> 452.19406 | J13: ='P L '!I53 -> 452.19406 | K13: ='P L '!J53 -> 452.19406 | L13: ='P L '!K53 -> 452.19406 | M13: ='P L '!L53 -> 452.19406
B14: Interest on Term Loan | E14: ='P L '!D50 -> 254.71875 | F14: ='P L '!E50 -> 240.1125 | G14: ='P L '!F50 -> 217.7875 | H14: ='P L '!G50 -> 186.675 | I14: ='P L '!H50 -> 147.25 | J14: ='P L '!I50 -> 99.0375 | K14: ='P L '!J50 -> 45.125 | L14: ='P L '!K50 -> 2.375 | M14: ='P L '!L50 -> 0
B15: Residual Value of Fixed Assets | L15: =0.5*'B S '!L13 -> 598.15591 | N15: *
B17: TOTAL CASH INFLOW | D17: =SUM(D10:D15) -> 0 | E17: =SUM(E10:E15) -> 982.85417 | F17: =SUM(F10:F15) -> 1009.0637 | G17: =SUM(G10:G15) -> 1050.9727 | H17: =SUM(H10:H15) -> 1060.8673 | I17: =SUM(I10:I15) -> 996.29794 | J17: =SUM(J10:J15) -> 850.42366 | K17: =SUM(K10:K15) -> 770.91452 | ... M17: =SUM(M10:M15) -> #VALUE!
B19: CASH OUTFLOWS
B21: Capital Expenditure | D21: ='CAPITAL COST'!D36+'CAPITAL COST'!D34 -> 4263.8643 | E21: 0 | F21: 0 | G21: 0 | H21: 0 | I21: 0 | J21: 0 | K21: 0 | L21: 0 | M21: 0
B23: TOTAL CASH OUTFLOW | D23: =SUM(D19:D22) -> 4263.8643 | E23: =SUM(E19:E22) -> 0 | F23: =SUM(F19:F22) -> 0 | G23: =SUM(G19:G22) -> 0 | H23: =SUM(H19:H22) -> 0 | I23: =SUM(I19:I22) -> 0 | J23: =SUM(J19:J22) -> 0 | K23: =SUM(K19:K22) -> 0 | ... M23: =SUM(M19:M22) -> 0
B25: NET CASH FLOW | D25: =D17-D23 -> -4263.8643 | E25: =E17-E23 -> 982.85417 | F25: =F17-F23 -> 1009.0637 | G25: =G17-G23 -> 1050.9727 | H25: =H17-H23 -> 1060.8673 | I25: =I17-I23 -> 996.29794 | J25: =J17-J23 -> 850.42366 | K25: =K17-K23 -> 770.91452 | ... M25: =M17-M23 -> #VALUE!
B27: Discounting Factor | D27: 1 | E27: 1 | F27: =1/(1+Q10) -> 0.89074163 | G27: =+F27/(1+$Q$10) -> 0.79342065 | H27: =+G27/(1+$Q$10) -> 0.70673281 | I27: =+H27/(1+$Q$10) -> 0.62951633 | J27: =+I27/(1+$Q$10) -> 0.56073641 | K27: =+J27/(1+$Q$10) -> 0.49947126 | L27: =+K27/(1+$Q$10) -> 0.44489985 | M27: =+L27/(1+$Q$10) -> 0.39629082
B28: Present Value | D28: =D25*D27 -> -4263.8643 | E28: =E25*E27 -> 982.85417 | F28: =F25*F27 -> 898.81505 | G28: =G25*G27 -> 833.86343 | H28: =H25*H27 -> 749.74972 | I28: =I25*I27 -> 627.18583 | J28: =J25*J27 -> 476.86351 | K28: =K25*K27 -> 385.04965 | ... M28: =M25*M27 -> #VALUE!
B31: Net Present Value (Rs.) | E31: =SUM(D28:L28) -> 1254.6773
B33: The Internal Rate of Return is | E33: =Q10 -> 0.12266
B36: * Residual value of fixed assets has been considered at 50% of Book WDV

Sheet P  L _Case_IV
D2: (28)
D4: ANNEXURE III
C5: Projected Profitability
J6: Rs. In Lacs
A8: Year | D8: 1 | E8: 2 | F8: 3 | G8: 4 | H8: 5 | I8: 6 | J8: 7 | K8: 8 | L8: 9
A10: Room Charges | D10: =SALESPROJECTION!E74 -> 3668.25 | E10: =SALESPROJECTION!F74 -> 3668.25 | F10: =SALESPROJECTION!G74 -> 3668.25 | G10: =SALESPROJECTION!H74 -> 3668.25 | H10: =SALESPROJECTION!I74 -> 3668.25 | I10: =SALESPROJECTION!J74 -> 3668.25 | J10: =SALESPROJECTION!K74 -> 3668.25 | K10: =SALESPROJECTION!L74 -> 3668.25 | L10: =SALESPROJECTION!M74 -> 3668.25
A11: F & B Sales | D11: =SALESPROJECTION!E75 -> 884.33569 | E11: =SALESPROJECTION!F75 -> 884.33569 | F11: =SALESPROJECTION!G75 -> 884.33569 | G11: =SALESPROJECTION!H75 -> 884.33569 | H11: =SALESPROJECTION!I75 -> 884.33569 | I11: =SALESPROJECTION!J75 -> 884.33569 | J11: =SALESPROJECTION!K75 -> 884.33569 | K11: =SALESPROJECTION!L75 -> 884.33569 | L11: =SALESPROJECTION!M75 -> 884.33569
A12: Banquet Hall Receipts | D12: =SALESPROJECTION!E76 -> 195 | E12: =SALESPROJECTION!F76 -> 195 | F12: =SALESPROJECTION!G76 -> 195 | G12: =SALESPROJECTION!H76 -> 195 | H12: =SALESPROJECTION!I76 -> 195 | I12: =SALESPROJECTION!J76 -> 195 | J12: =SALESPROJECTION!K76 -> 195 | K12: =SALESPROJECTION!L76 -> 195 | L12: =SALESPROJECTION!M76 -> 195
A13: Conference Hall Receipts | D13: =SALESPROJECTION!E79 -> 45 | E13: =SALESPROJECTION!F79 -> 45 | F13: =SALESPROJECTION!G79 -> 45 | G13: =SALESPROJECTION!H79 -> 45 | H13: =SALESPROJECTION!I79 -> 45 | I13: =SALESPROJECTION!J79 -> 45 | J13: =SALESPROJECTION!K79 -> 45 | K13: =SALESPROJECTION!L79 -> 45 | L13: =SALESPROJECTION!M79 -> 45
A14: Other Income | D14: =SALESPROJECTION!E80 -> 125.7522 | E14: =SALESPROJECTION!F80 -> 125.7522 | F14: =SALESPROJECTION!G80 -> 125.7522 | G14: =SALESPROJECTION!H80 -> 125.7522 | H14: =SALESPROJECTION!I80 -> 125.7522 | I14: =SALESPROJECTION!J80 -> 125.7522 | J14: =SALESPROJECTION!K80 -> 125.7522 | K14: =SALESPROJECTION!L80 -> 125.7522 | L14: =SALESPROJECTION!M80 -> 125.7522
A15: Gross Revenue Receipt | D15: =SUM(D10:D14) -> 4918.3379 | E15: =SUM(E10:E14) -> 4918.3379 | F15: =SUM(F10:F14) -> 4918.3379 | G15: =SUM(G10:G14) -> 4918.3379 | H15: =SUM(H10:H14) -> 4918.3379 | I15: =SUM(I10:I14) -> 4918.3379 | J15: =SUM(J10:J14) -> 4918.3379 | K15: =SUM(K10:K14) -> 4918.3379 | L15: =SUM(L10:L14) -> 4918.3379 | T15: =E15-SALESPROJECTION!F81 -> -111.75 | U15: =F15-SALESPROJECTION!G81 -> -111.75 | V15: =G15-SALESPROJECTION!H81 -> -111.75 | W15: =H15-SALESPROJECTION!I81 -> -111.75 | X15: =I15-SALESPROJECTION!J81 -> -111.75 | Y15: =J15-SALESPROJECTION!K81 -> -111.75
A16: Envisaged Occupancy | D16: =40% -> 0.4 | E16: =D16+0.05 -> 0.45 | F16: =E16+0.05 -> 0.5 | G16: =F16+0.05 -> 0.55 | H16: =G16+5% -> 0.6 | I16: =H16 -> 0.6 | J16: =I16 -> 0.6 | K16: =J16 -> 0.6 | L16: =K16 -> 0.6
A18: Projected Sales
A20: Room Sales | D20: =D16*D10 -> 1467.3 | E20: =E16*E10 -> 1650.7125 | F20: =F16*F10 -> 1834.125 | G20: =G16*G10 -> 2017.5375 | H20: =H16*H10 -> 2200.95 | I20: =I16*I10 -> 2200.95 | J20: =J16*J10 -> 2200.95 | K20: =K16*K10 -> 2200.95 | L20: =L16*L10 -> 2200.95
A21: F & B Sales | D21: =$D$16*D11 -> 353.73428 | E21: =$E$16*E11 -> 397.95106 | F21: =$F$16*F11 -> 442.16784 | G21: =$G$16*G11 -> 486.38463 | H21: =$H$16*H11 -> 530.60141 | I21: =$I$16*I11 -> 530.60141 | J21: =$J$16*J11 -> 530.60141 | K21: =$K$16*K11 -> 530.60141 | L21: =$K$16*L11 -> 530.60141
A22: Banquet Hall Receipts | D22: =$D$16*D12 -> 78 | E22: =$E$16*E12 -> 87.75 | F22: =$F$16*F12 -> 97.5 | G22: =$G$16*G12 -> 107.25 | H22: =$H$16*H12 -> 117 | I22: =$I$16*I12 -> 117 | J22: =$J$16*J12 -> 117 | K22: =$K$16*K12 -> 117 | L22: =$K$16*L12 -> 117
A23: Conference Hall Receipts | D23: =$D$16*D13 -> 18 | E23: =$E$16*E13 -> 20.25 | F23: =$F$16*F13 -> 22.5 | G23: =$G$16*G13 -> 24.75 | H23: =$H$16*H13 -> 27 | I23: =$I$16*I13 -> 27 | J23: =$J$16*J13 -> 27 | K23: =$K$16*K13 -> 27 | L23: =$K$16*L13 -> 27
A24: Other Income | D24: =D16*D14 -> 50.300879 | E24: =E16*E14 -> 56.588489 | F24: =F16*F14 -> 62.876099 | G24: =G16*G14 -> 69.163708 | H24: =H16*H14 -> 75.451318 | I24: =I16*I14 -> 75.451318 | J24: =J16*J14 -> 75.451318 | K24: =K16*K14 -> 75.451318 | L24: =L16*L14 -> 75.451318
A25: Total Projected Sales | D25: =SUM(D20:D24) -> 1967.3352 | E25: =SUM(E20:E24) -> 2213.252 | F25: =SUM(F20:F24) -> 2459.1689 | G25: =SUM(G20:G24) -> 2705.0858 | H25: =SUM(H20:H24) -> 2951.0027 | I25: =SUM(I20:I24) -> 2951.0027 | J25: =SUM(J20:J24) -> 2951.0027 | K25: =SUM(K20:K24) -> 2951.0027 | L25: =SUM(L20:L24) -> 2951.0027
A27: Revenue Expenses | B27: As | C27: of
A29: Food & Beverages Cost | B29: 0.4 | C29: F & B sales | D29: =ROUND(B29*D21,2) -> 141.49 | E29: =B29*E21 -> 159.18042 | F29: =B29*F21 -> 176.86714 | G29: =B29*G21 -> 194.55385 | H29: =B29*H21 -> 212.24057 | I29: =B29*I21 -> 212.24057 | J29: =$B$29*J21 -> 212.24057 | K29: =$B$29*K21 -> 212.24057 | L29: =$B$29*L21 -> 212.24057
A30: Banquet & Conference Hall Expenses | B30: 0.25 | C30: B & C Receipts | D30: =(D22+D23)*$B$30 -> 24 | E30: =(E22+E23)*$B$30 -> 27 | F30: =(F22+F23)*$B$30 -> 30 | G30: =(G22+G23)*$B$30 -> 33 | H30: =(H22+H23)*$B$30 -> 36 | I30: =(I22+I23)*$B$30 -> 36 | J30: =(J22+J23)*$B$30 -> 36 | K30: =(K22+K23)*$B$30 -> 36 | L30: =(L22+L23)*$B$30 -> 36
A31: Employee Related Expenses | B31: 0.09 | C31: Total Sales | D31: =B31*D25 -> 177.06016 | E31: =B31*E25*1.05 -> 209.15232 | F31: =B31*F25*1.1 -> 243.45773 | G31: =B31*G25*1.2 -> 292.14927 | H31: =B31*H25*1.2 -> 318.70829 | I31: =B31*I25*1.25 -> 331.98781 | J31: =$B$31*J25*1.3 -> 345.26732 | K31: =$B$31*K25*1.35 -> 358.54683 | L31: =$B$31*L25*1.4 -> 371.82634 | P31: Increasing
A32: Power, Fuel & Water Charges | B32: 0.075 | C32: Total Sales | D32: =ROUND(B32*D25,2) -> 147.55 | E32: =B32*E25 -> 165.9939 | F32: =B32*F25 -> 184.43767 | G32: =B32*G25 -> 202.88144 | H32: =B32*H25 -> 221.3252 | I32: =B32*I25 -> 221.3252 | J32: =$B$32*J25 -> 221.3252 | K32: =$B$32*K25 -> 221.3252 | L32: =$B$32*L25 -> 221.3252
A33: Repair & Maintenance | B33: 0.005 | C33: Assets | D33: =depreciation!D147*0.5% -> 19.058351 | E33: =depreciation!E147*1% -> 33.594762 | F33: =depreciation!F147*1.25% -> 37.528526 | G33: =depreciation!G147*2.5% -> 64.002201 | H33: =depreciation!H147*2.5% -> 55.69735 | I33: =depreciation!I147*3% -> 56.570998 | J33: =depreciation!J147*3.5% -> 54.197705 | K33: =depreciation!K147*4% -> 47.852472 | L33: =depreciation!L147*4.75% -> 39.383093 | P33: Increasing
